Workbook

Sheet Atk Speed Calc
A1: DESKTOP ONLY. DO NOT ACCESS THIS CALCULATOR FROM MOBILE
A3: Patch 1.23.3.12 [Reshiram]
A4: Mewtwo Y | B4: 1 | C4: 2 | D4: 3 | E4: 4 | F4: 5 | G4: 6 | H4: 7 | I4: 8 | J4: 9 | K4: 10 | L4: 11 | M4: 12 | N4: 13 | O4: 14 | P4: 15
A5: Base Attack Speed | B5: {=INDEX('Base Atk Speed'!$A:$P,MATCH($A$4,'Base Atk Speed'!$A:$A,0),MATCH(B4,'Base Atk Speed'!1:1,0))} -> 10 | C5: {=INDEX('Base Atk Speed'!$A:$P,MATCH($A$4,'Base Atk Speed'!$A:$A,0),MATCH(C4,'Base Atk Speed'!1:1,0))} -> 11.42 | D5: {=INDEX('Base Atk Speed'!$A:$P,MATCH($A$4,'Base Atk Speed'!$A:$A,0),MATCH(D4,'Base Atk Speed'!1:1,0))} -> 12.99 | E5: {=INDEX('Base Atk Speed'!$A:$P,MATCH($A$4,'Base Atk Speed'!$A:$A,0),MATCH(E4,'Base Atk Speed'!1:1,0))} -> 14.71 | F5: {=INDEX('Base Atk Speed'!$A:$P,MATCH($A$4,'Base Atk Speed'!$A:$A,0),MATCH(F4,'Base Atk Speed'!1:1,0))} -> 16.6 | G5: {=INDEX('Base Atk Speed'!$A:$P,MATCH($A$4,'Base Atk Speed'!$A:$A,0),MATCH(G4,'Base Atk Speed'!1:1,0))} -> 18.68 | H5: {=INDEX('Base Atk Speed'!$A:$P,MATCH($A$4,'Base Atk Speed'!$A:$A,0),MATCH(H4,'Base Atk Speed'!1:1,0))} -> 20.97 | I5: {=INDEX('Base Atk Speed'!$A:$P,MATCH($A$4,'Base Atk Speed'!$A:$A,0),MATCH(I4,'Base Atk Speed'!1:1,0))} -> 23.49 | ... P5: {=INDEX('Base Atk Speed'!$A:$P,MATCH($A$4,'Base Atk Speed'!$A:$A,0),MATCH(P4,'Base Atk Speed'!1:1,0))} -> 49.99 | R5: DO NOT EVER PRESS DELETE KEY
A6: Additional Attack Speed | B6: =IF($G$9=TRUE,'Atk Speed Boosts'!$C$9,0) +IF($G$10=TRUE,'Atk Speed Boosts'!$C$10,0)+$G$11 +IF(AND($A$4="Absol",$I$9="Feint",$K$9=TRUE,B4<5),'Atk Speed Boosts'!$C$11,0) +IF(AND($A$4="Absol",$I$10="Night Slash",$K$10=TRUE,B4>4),'Atk Speed Boosts'!$C$12,0) +IF(AND($A$4="Absol",$I$11="Sucker Punch+",$K$11=TRUE,B4>12),'Atk Speed Boosts'!$C$13,0) +IF(AND($A$4="Aegislash",$I$9="Sword Stance",$K$9=TRUE,B4>6),'Atk Speed Boosts'!$C$14,0) +IF(AND($A$4="Aegislash",$I$10="Shield Stance",$K$10=TRUE,B4>6),'Atk Speed Boosts'!$C$15,0) +IF(AND($A$4="Aegislash",$I$11="Stance Change",$K$11=TRUE,B4>6),'Atk Speed Boosts'!$C$16,0) +IF(AND($A$4="Azumarill",$I$9="Aqua Tail",$K$9=TRUE,B4>3),'Atk Speed Boosts'!$C$20,0) +IF(AND($A$4="Blaziken",$I$9="Punch Style",$K$9=TRUE,OR(B4<5,B4>7)),'Atk Speed Boosts'!$C$22,0) +IF(AND($A$4="Buzzwole",$I$9="Beast Boost Assist",$K$9=TRUE),'Atk Speed Boosts'!$C$24,0) +IF(AND($A$4="Buzzwole",$I$10="Beast Boost KO",$K$10=TRUE),'Atk Speed Boosts'!$C$25,0) +IF(AND($A$4="Buzzwole",$I$11="Lunge",$K$11=TRUE,B4>6),'Atk Speed Boosts'!$C$26,0) +IF(AND($A$4="Ceruledge",$I$9="Take Down",$K$9=TRUE,B4<7),'Atk Speed Boosts'!$C$27,0) +IF(AND($A$4="Ceruledge",$I$10="Flame Charge",$K$10=TRUE,B4>6),'Atk Speed Boosts'!$C$28,0) +IF(AND($A$4="Cinderace",$I$9="Blaze",$K$9=TRUE),'Atk Speed Boosts'!$C$33,0) +IF(AND($A$4="Cinderace",$I$10="Blaze Kick+",$K$10=TRUE,B4>10),'Atk Speed Boosts'!$C$34,0) +IF(AND($A$4="Cinderace",$I$11="Unite Buff",$K$11=TRUE,B4>8),'Atk Speed Boosts'!$C$35,0) +IF(AND($A$4="Decidueye",$I$9="Auto Attack",$K$9=TRUE),'Atk Speed Boosts'!$C$41*$L$9,0) +IF(AND($A$4="Decidueye",$I$10="Leafage",$K$10=TRUE,B4<7),'Atk Speed Boosts'!$C$42,0) +IF(AND($A$4="Decidueye",$I$11="Razor Leaf",$K$11=TRUE,B4>6),'Atk Speed Boosts'!$C$43+'Atk Speed Boosts'!$D$43*(B4-1),0) +IF(AND($A$4="Dragapult",$I$9="Quick Attack",$K$9=TRUE,B4<5),'Atk Speed Boosts'!$C$47,0) +IF(AND($A$4="Dragapult",$I$10="Dragon Dance",$K$10=TRUE,B4>4),'Atk Speed Boosts'!$C$48,0) +IF(AND($A$4="Dragapult",$I$11="Phantom Force",$K$11=TRUE,B4>4),'Atk Speed Boosts'!$C$49,0) +IF(AND($A$4="Dragonite",$I$9="Dragon Dance",$K$9=TRUE,B4>4),'Atk Speed Boosts'!$C$50,0) +IF(AND($A$4="Dragonite",$I$10="Outrage",$K$10=TRUE,B4>7),'Atk Speed Boosts'!$C$51,0) +IF(AND($A$4="Dragonite",$I$11="Unite Buff",$K$11=TRUE,B4>8),'Atk Speed Boosts'!$C$52,0) +IF(AND($A$4="Duraludon",$I$9="Flash Cannon",$K$9=TRUE,B4>4),'Atk Speed Boosts'!$C$53-20*$L$9,0) +IF(AND($A$4="Duraludon",$I$10="Unite Buff",$K$10=TRUE,B4>8),'Atk Speed Boosts'!$C$54,0) +IF(AND($A$4="Empoleon",$I$9="Aqua Jet",$K$9=TRUE,B4>4),'Atk Speed Boosts'!$C$56,0) +IF(AND($A$4="Falinks",$I$9="Bulk Up",$K$9=TRUE,B4<6),'Atk Speed Boosts'!$C$58,0) +IF(AND($A$4="Feraligatr",$I$9="Crunch",$K$9=TRUE,B4<4),'Atk Speed Boosts'!$C$59,0) +IF(AND($A$4="Feraligatr",$I$9="Unite Buff",$K$9=TRUE,B4<8),'Atk Speed Boosts'!$C$60,0) +IF(AND($A$4="Garchomp",$I$9="Boosted Attack",$K$9=TRUE),'Atk Speed Boosts'!$C$61+'Atk Speed Boosts'!$D$61*(B4-1),0) +IF(AND($A$4="Garchomp",$I$10="Sand Attack",$K$10=TRUE,B4<5),'Atk Speed Boosts'!$C$62,0) +IF(AND($A$4="Glaceon",$I$9="Eevee Bond",$K$9=TRUE),'Atk Speed Boosts'!$C$65,0) +IF(AND($A$4="Glaceon",$I$10="Ice Shard",$K$10=TRUE,B4>5,B4<12),'Atk Speed Boosts'!$C$66,0) +IF(AND($A$4="Glaceon",$I$11="Ice Shard+",$K$11=TRUE,B4>11),'Atk Speed Boosts'!$C$67,0) +IF(AND($A$4="Glaceon",$I$12="Unite Buff",$K$12=TRUE,B4>7),'Atk Speed Boosts'!$C$68,0) +IF(AND($A$4="Greninja",$I$9="Unite Buff",$K$9=TRUE,B4>8),'Atk Speed Boosts'!$C$71,0) +IF(AND($A$4="Gyarados",$I$9="Evolution",$K$9=TRUE),'Atk Speed Boosts'!$C$72,0) +IF(AND($A$4="Gyarados",$I$10="Dragon Breath",$K$10=TRUE),'Atk Speed Boosts'!$C$73+'Atk Speed Boosts'!$D$73*$L$10,0) +IF(AND($A$4="Gyarados [Mega]",$I$9="Evolution",$K$9=TRUE),'Atk Speed Boosts'!$C$74,0) +IF(AND($A$4="Gyarados [Mega]",$I$10="Dragon Breath",$K$10=TRUE),'Atk Speed Boosts'!$C$75+'Atk Speed Boosts'!$D$75*$L$10,0) +IF(AND($A$4="Inteleon",$I$9="Unite Buff",$K$9=TRUE,B4>8),'Atk Speed Boosts'!$C$78,0) +IF(AND($A$4="Machamp",$I$9="Bulk Up",$K$9=TRUE,B4<5),'Atk Speed Boosts'!$C$85,0) +IF(AND($A$4="Machamp",$I$10="Submission",$K$10=TRUE,B4>4,B4<11),'Atk Speed Boosts'!$C$86,0) +IF(AND($A$4="Machamp",$I$11="Submission+",$K$11=TRUE,B4>10),'Atk Speed Boosts'!$C$87,0) +IF(AND($A$4="Machamp",$I$12="Unite Buff",$K$12=TRUE,B4>8),'Atk Speed Boosts'!$C$88,0) +IF(AND($A$4="Meowscarada",$I$9="Hone Claws",$K$9=TRUE,B4<7),'Atk Speed Boosts'!$C$91,0) +IF(AND($A$4="Meowscarada",$I$10="Trail Blaze",$K$10=TRUE,B4>6),'Atk Speed Boosts'!$C$92,0) +IF(AND($A$4="Mewtwo Y",$I$9="Pressure",$K$9=TRUE),'Atk Speed Boosts'!$C$97*$L$9,0) +IF(AND($A$4="Mewtwo Y",$I$10="Mega Evolution",$K$10=TRUE,B4>4),'Atk Speed Boosts'!$C$98,0) +IF(AND($A$4="Ninetales",$I$9="Aurora Veil",$K$9=TRUE,B4>5),'Atk Speed Boosts'!$C$103,0) +IF(AND($A$4="Pawmot",$I$9="Fighter Mode",$K$9=TRUE,B4>8),'Atk Speed Boosts'!$C$105*$L$9,0) +IF(AND($A$4="Pawmot",$I$10="Unite Buff",$K$10=TRUE,B4>8),'Atk Speed Boosts'!$C$105,0) +IF(AND($A$4="Raichu",$I$9="Stored Power",$K$9=TRUE,B4>4),'Atk Speed Boosts'!$C$110,0) +IF(AND($A$4="Raichu",$I$10="Unite Buff",$K$10=TRUE,B4>8),'Atk Speed Boosts'!$C$111,0) +IF(AND($A$4="Tsareena",$I$9="Triple Axel",$K$9=TRUE,B4>4),('Atk Speed Boosts'!$C$126+'Atk Speed Boosts'!$D$126*(B4-1))*$L$9,0) +IF(AND($A$4="Zacian",$I$9="Metal Claw",$K$9=TRUE,B4>4),'Atk Speed Boosts'!$C$135,0) +IF(AND($A$4="Zeraora",$I$9="Agility",$K$9=TRUE,B4<5),'Atk Speed Boosts'!$C$137,0) +IF(AND($A$4="Zeraora",$I$10="Volt Switch",$K$10=TRUE,B4>4,B4<11),'Atk Speed Boosts'!$C$138,0) +IF(AND($A$4="Zeraora",$I$11="Volt Switch+",$K$11=TRUE,B4>10),'Atk Speed Boosts'!$C$139,0) +IF(AND($A$4="Zeraora",$I$12="Unite Buff",$K$12=TRUE,B4>8),'Atk Speed Boosts'!$C$140,0) -> 0 | C6: =IF($G$9=TRUE,'Atk Speed Boosts'!$C$9,0) +IF($G$10=TRUE,'Atk Speed Boosts'!$C$10,0)+$G$11 +IF(AND($A$4="Absol",$I$9="Feint",$K$9=TRUE,C4<5),'Atk Speed Boosts'!$C$11,0) +IF(AND($A$4="Absol",$I$10="Night Slash",$K$10=TRUE,C4>4),'Atk Speed Boosts'!$C$12,0) +IF(AND($A$4="Absol",$I$11="Sucker Punch+",$K$11=TRUE,C4>12),'Atk Speed Boosts'!$C$13,0) +IF(AND($A$4="Aegislash",$I$9="Sword Stance",$K$9=TRUE,C4>6),'Atk Speed Boosts'!$C$14,0) +IF(AND($A$4="Aegislash",$I$10="Shield Stance",$K$10=TRUE,C4>6),'Atk Speed Boosts'!$C$15,0) +IF(AND($A$4="Aegislash",$I$11="Stance Change",$K$11=TRUE,C4>6),'Atk Speed Boosts'!$C$16,0) +IF(AND($A$4="Azumarill",$I$9="Aqua Tail",$K$9=TRUE,C4>3),'Atk Speed Boosts'!$C$20,0) +IF(AND($A$4="Blaziken",$I$9="Punch Style",$K$9=TRUE,OR(C4<5,C4>7)),'Atk Speed Boosts'!$C$22,0) +IF(AND($A$4="Buzzwole",$I$9="Beast Boost Assist",$K$9=TRUE),'Atk Speed Boosts'!$C$24,0) +IF(AND($A$4="Buzzwole",$I$10="Beast Boost KO",$K$10=TRUE),'Atk Speed Boosts'!$C$25,0) +IF(AND($A$4="Buzzwole",$I$11="Lunge",$K$11=TRUE,C4>6),'Atk Speed Boosts'!$C$26,0) +IF(AND($A$4="Ceruledge",$I$9="Take Down",$K$9=TRUE,C4<7),'Atk Speed Boosts'!$C$27,0) +IF(AND($A$4="Ceruledge",$I$10="Flame Charge",$K$10=TRUE,C4>6),'Atk Speed Boosts'!$C$28,0) +IF(AND($A$4="Cinderace",$I$9="Blaze",$K$9=TRUE),'Atk Speed Boosts'!$C$33,0) +IF(AND($A$4="Cinderace",$I$10="Blaze Kick+",$K$10=TRUE,C4>10),'Atk Speed Boosts'!$C$34,0) +IF(AND($A$4="Cinderace",$I$11="Unite Buff",$K$11=TRUE,C4>8),'Atk Speed Boosts'!$C$35,0) +IF(AND($A$4="Decidueye",$I$9="Auto Attack",$K$9=TRUE),'Atk Speed Boosts'!$C$41*$L$9,0) +IF(AND($A$4="Decidueye",$I$10="Leafage",$K$10=TRUE,C4<7),'Atk Speed Boosts'!$C$42,0) +IF(AND($A$4="Decidueye",$I$11="Razor Leaf",$K$11=TRUE,C4>6),'Atk Speed Boosts'!$C$43+'Atk Speed Boosts'!$D$43*(C4-1),0) +IF(AND($A$4="Dragapult",$I$9="Quick Attack",$K$9=TRUE,C4<5),'Atk Speed Boosts'!$C$47,0) +IF(AND($A$4="Dragapult",$I$10="Dragon Dance",$K$10=TRUE,C4>4),'Atk Speed Boosts'!$C$48,0) +IF(AND($A$4="Dragapult",$I$11="Phantom Force",$K$11=TRUE,C4>4),'Atk Speed Boosts'!$C$49,0) +IF(AND($A$4="Dragonite",$I$9="Dragon Dance",$K$9=TRUE,C4>4),'Atk Speed Boosts'!$C$50,0) +IF(AND($A$4="Dragonite",$I$10="Outrage",$K$10=TRUE,C4>7),'Atk Speed Boosts'!$C$51,0) +IF(AND($A$4="Dragonite",$I$11="Unite Buff",$K$11=TRUE,C4>8),'Atk Speed Boosts'!$C$52,0) +IF(AND($A$4="Duraludon",$I$9="Flash Cannon",$K$9=TRUE,C4>4),'Atk Speed Boosts'!$C$53-20*$L$9,0) +IF(AND($A$4="Duraludon",$I$10="Unite Buff",$K$10=TRUE,C4>8),'Atk Speed Boosts'!$C$54,0) +IF(AND($A$4="Empoleon",$I$9="Aqua Jet",$K$9=TRUE,C4>4),'Atk Speed Boosts'!$C$56,0) +IF(AND($A$4="Falinks",$I$9="Bulk Up",$K$9=TRUE,C4<6),'Atk Speed Boosts'!$C$58,0) +IF(AND($A$4="Feraligatr",$I$9="Crunch",$K$9=TRUE,C4<4),'Atk Speed Boosts'!$C$59,0) +IF(AND($A$4="Feraligatr",$I$9="Unite Buff",$K$9=TRUE,C4<8),'Atk Speed Boosts'!$C$60,0) +IF(AND($A$4="Garchomp",$I$9="Boosted Attack",$K$9=TRUE),'Atk Speed Boosts'!$C$61+'Atk Speed Boosts'!$D$61*(C4-1),0) +IF(AND($A$4="Garchomp",$I$10="Sand Attack",$K$10=TRUE,C4<5),'Atk Speed Boosts'!$C$62,0) +IF(AND($A$4="Glaceon",$I$9="Eevee Bond",$K$9=TRUE),'Atk Speed Boosts'!$C$65,0) +IF(AND($A$4="Glaceon",$I$10="Ice Shard",$K$10=TRUE,C4>5,C4<12),'Atk Speed Boosts'!$C$66,0) +IF(AND($A$4="Glaceon",$I$11="Ice Shard+",$K$11=TRUE,C4>11),'Atk Speed Boosts'!$C$67,0) +IF(AND($A$4="Glaceon",$I$12="Unite Buff",$K$12=TRUE,C4>7),'Atk Speed Boosts'!$C$68,0) +IF(AND($A$4="Greninja",$I$9="Unite Buff",$K$9=TRUE,C4>8),'Atk Speed Boosts'!$C$71,0) +IF(AND($A$4="Gyarados",$I$9="Evolution",$K$9=TRUE),'Atk Speed Boosts'!$C$72,0) +IF(AND($A$4="Gyarados",$I$10="Dragon Breath",$K$10=TRUE),'Atk Speed Boosts'!$C$73+'Atk Speed Boosts'!$D$73*$L$10,0) +IF(AND($A$4="Gyarados [Mega]",$I$9="Evolution",$K$9=TRUE),'Atk Speed Boosts'!$C$74,0) +IF(AND($A$4="Gyarados [Mega]",$I$10="Dragon Breath",$K$10=TRUE),'Atk Speed Boosts'!$C$75+'Atk Speed Boosts'!$D$75*$L$10,0) +IF(AND($A$4="Inteleon",$I$9="Unite Buff",$K$9=TRUE,C4>8),'Atk Speed Boosts'!$C$78,0) +IF(AND($A$4="Machamp",$I$9="Bulk Up",$K$9=TRUE,C4<5),'Atk Speed Boosts'!$C$85,0) +IF(AND($A$4="Machamp",$I$10="Submission",$K$10=TRUE,C4>4,C4<11),'Atk Speed Boosts'!$C$86,0) +IF(AND($A$4="Machamp",$I$11="Submission+",$K$11=TRUE,C4>10),'Atk Speed Boosts'!$C$87,0) +IF(AND($A$4="Machamp",$I$12="Unite Buff",$K$12=TRUE,C4>8),'Atk Speed Boosts'!$C$88,0) +IF(AND($A$4="Meowscarada",$I$9="Hone Claws",$K$9=TRUE,C4<7),'Atk Speed Boosts'!$C$91,0) +IF(AND($A$4="Meowscarada",$I$10="Trail Blaze",$K$10=TRUE,C4>6),'Atk Speed Boosts'!$C$92,0) +IF(AND($A$4="Mewtwo Y",$I$9="Pressure",$K$9=TRUE),'Atk Speed Boosts'!$C$97*$L$9,0) +IF(AND($A$4="Mewtwo Y",$I$10="Mega Evolution",$K$10=TRUE,C4>4),'Atk Speed Boosts'!$C$98,0) +IF(AND($A$4="Ninetales",$I$9="Aurora Veil",$K$9=TRUE,C4>5),'Atk Speed Boosts'!$C$103,0) +IF(AND($A$4="Pawmot",$I$9="Fighter Mode",$K$9=TRUE,C4>8),'Atk Speed Boosts'!$C$105*$L$9,0) +IF(AND($A$4="Pawmot",$I$10="Unite Buff",$K$10=TRUE,C4>8),'Atk Speed Boosts'!$C$105,0) +IF(AND($A$4="Raichu",$I$9="Stored Power",$K$9=TRUE,C4>4),'Atk Speed Boosts'!$C$110,0) +IF(AND($A$4="Raichu",$I$10="Unite Buff",$K$10=TRUE,C4>8),'Atk Speed Boosts'!$C$111,0) +IF(AND($A$4="Tsareena",$I$9="Triple Axel",$K$9=TRUE,C4>4),('Atk Speed Boosts'!$C$126+'Atk Speed Boosts'!$D$126*(C4-1))*$L$9,0) +IF(AND($A$4="Zacian",$I$9="Metal Claw",$K$9=TRUE,C4>4),'Atk Speed Boosts'!$C$135,0) +IF(AND($A$4="Zeraora",$I$9="Agility",$K$9=TRUE,C4<5),'Atk Speed Boosts'!$C$137,0) +IF(AND($A$4="Zeraora",$I$10="Volt Switch",$K$10=TRUE,C4>4,C4<11),'Atk Speed Boosts'!$C$138,0) +IF(AND($A$4="Zeraora",$I$11="Volt Switch+",$K$11=TRUE,C4>10),'Atk Speed Boosts'!$C$139,0) +IF(AND($A$4="Zeraora",$I$12="Unite Buff",$K$12=TRUE,C4>8),'Atk Speed Boosts'!$C$140,0) -> 0 | D6: =IF($G$9=TRUE,'Atk Speed Boosts'!$C$9,0) +IF($G$10=TRUE,'Atk Speed Boosts'!$C$10,0)+$G$11 +IF(AND($A$4="Absol",$I$9="Feint",$K$9=TRUE,D4<5),'Atk Speed Boosts'!$C$11,0) +IF(AND($A$4="Absol",$I$10="Night Slash",$K$10=TRUE,D4>4),'Atk Speed Boosts'!$C$12,0) +IF(AND($A$4="Absol",$I$11="Sucker Punch+",$K$11=TRUE,D4>12),'Atk Speed Boosts'!$C$13,0) +IF(AND($A$4="Aegislash",$I$9="Sword Stance",$K$9=TRUE,D4>6),'Atk Speed Boosts'!$C$14,0) +IF(AND($A$4="Aegislash",$I$10="Shield Stance",$K$10=TRUE,D4>6),'Atk Speed Boosts'!$C$15,0) +IF(AND($A$4="Aegislash",$I$11="Stance Change",$K$11=TRUE,D4>6),'Atk Speed Boosts'!$C$16,0) +IF(AND($A$4="Azumarill",$I$9="Aqua Tail",$K$9=TRUE,D4>3),'Atk Speed Boosts'!$C$20,0) +IF(AND($A$4="Blaziken",$I$9="Punch Style",$K$9=TRUE,OR(D4<5,D4>7)),'Atk Speed Boosts'!$C$22,0) +IF(AND($A$4="Buzzwole",$I$9="Beast Boost Assist",$K$9=TRUE),'Atk Speed Boosts'!$C$24,0) +IF(AND($A$4="Buzzwole",$I$10="Beast Boost KO",$K$10=TRUE),'Atk Speed Boosts'!$C$25,0) +IF(AND($A$4="Buzzwole",$I$11="Lunge",$K$11=TRUE,D4>6),'Atk Speed Boosts'!$C$26,0) +IF(AND($A$4="Ceruledge",$I$9="Take Down",$K$9=TRUE,D4<7),'Atk Speed Boosts'!$C$27,0) +IF(AND($A$4="Ceruledge",$I$10="Flame Charge",$K$10=TRUE,D4>6),'Atk Speed Boosts'!$C$28,0) +IF(AND($A$4="Cinderace",$I$9="Blaze",$K$9=TRUE),'Atk Speed Boosts'!$C$33,0) +IF(AND($A$4="Cinderace",$I$10="Blaze Kick+",$K$10=TRUE,D4>10),'Atk Speed Boosts'!$C$34,0) +IF(AND($A$4="Cinderace",$I$11="Unite Buff",$K$11=TRUE,D4>8),'Atk Speed Boosts'!$C$35,0) +IF(AND($A$4="Decidueye",$I$9="Auto Attack",$K$9=TRUE),'Atk Speed Boosts'!$C$41*$L$9,0) +IF(AND($A$4="Decidueye",$I$10="Leafage",$K$10=TRUE,D4<7),'Atk Speed Boosts'!$C$42,0) +IF(AND($A$4="Decidueye",$I$11="Razor Leaf",$K$11=TRUE,D4>6),'Atk Speed Boosts'!$C$43+'Atk Speed Boosts'!$D$43*(D4-1),0) +IF(AND($A$4="Dragapult",$I$9="Quick Attack",$K$9=TRUE,D4<5),'Atk Speed Boosts'!$C$47,0) +IF(AND($A$4="Dragapult",$I$10="Dragon Dance",$K$10=TRUE,D4>4),'Atk Speed Boosts'!$C$48,0) +IF(AND($A$4="Dragapult",$I$11="Phantom Force",$K$11=TRUE,D4>4),'Atk Speed Boosts'!$C$49,0) +IF(AND($A$4="Dragonite",$I$9="Dragon Dance",$K$9=TRUE,D4>4),'Atk Speed Boosts'!$C$50,0) +IF(AND($A$4="Dragonite",$I$10="Outrage",$K$10=TRUE,D4>7),'Atk Speed Boosts'!$C$51,0) +IF(AND($A$4="Dragonite",$I$11="Unite Buff",$K$11=TRUE,D4>8),'Atk Speed Boosts'!$C$52,0) +IF(AND($A$4="Duraludon",$I$9="Flash Cannon",$K$9=TRUE,D4>4),'Atk Speed Boosts'!$C$53-20*$L$9,0) +IF(AND($A$4="Duraludon",$I$10="Unite Buff",$K$10=TRUE,D4>8),'Atk Speed Boosts'!$C$54,0) +IF(AND($A$4="Empoleon",$I$9="Aqua Jet",$K$9=TRUE,D4>4),'Atk Speed Boosts'!$C$56,0) +IF(AND($A$4="Falinks",$I$9="Bulk Up",$K$9=TRUE,D4<6),'Atk Speed Boosts'!$C$58,0) +IF(AND($A$4="Feraligatr",$I$9="Crunch",$K$9=TRUE,D4<4),'Atk Speed Boosts'!$C$59,0) +IF(AND($A$4="Feraligatr",$I$9="Unite Buff",$K$9=TRUE,D4<8),'Atk Speed Boosts'!$C$60,0) +IF(AND($A$4="Garchomp",$I$9="Boosted Attack",$K$9=TRUE),'Atk Speed Boosts'!$C$61+'Atk Speed Boosts'!$D$61*(D4-1),0) +IF(AND($A$4="Garchomp",$I$10="Sand Attack",$K$10=TRUE,D4<5),'Atk Speed Boosts'!$C$62,0) +IF(AND($A$4="Glaceon",$I$9="Eevee Bond",$K$9=TRUE),'Atk Speed Boosts'!$C$65,0) +IF(AND($A$4="Glaceon",$I$10="Ice Shard",$K$10=TRUE,D4>5,D4<12),'Atk Speed Boosts'!$C$66,0) +IF(AND($A$4="Glaceon",$I$11="Ice Shard+",$K$11=TRUE,D4>11),'Atk Speed Boosts'!$C$67,0) +IF(AND($A$4="Glaceon",$I$12="Unite Buff",$K$12=TRUE,D4>7),'Atk Speed Boosts'!$C$68,0) +IF(AND($A$4="Greninja",$I$9="Unite Buff",$K$9=TRUE,D4>8),'Atk Speed Boosts'!$C$71,0) +IF(AND($A$4="Gyarados",$I$9="Evolution",$K$9=TRUE),'Atk Speed Boosts'!$C$72,0) +IF(AND($A$4="Gyarados",$I$10="Dragon Breath",$K$10=TRUE),'Atk Speed Boosts'!$C$73+'Atk Speed Boosts'!$D$73*$L$10,0) +IF(AND($A$4="Gyarados [Mega]",$I$9="Evolution",$K$9=TRUE),'Atk Speed Boosts'!$C$74,0) +IF(AND($A$4="Gyarados [Mega]",$I$10="Dragon Breath",$K$10=TRUE),'Atk Speed Boosts'!$C$75+'Atk Speed Boosts'!$D$75*$L$10,0) +IF(AND($A$4="Inteleon",$I$9="Unite Buff",$K$9=TRUE,D4>8),'Atk Speed Boosts'!$C$78,0) +IF(AND($A$4="Machamp",$I$9="Bulk Up",$K$9=TRUE,D4<5),'Atk Speed Boosts'!$C$85,0) +IF(AND($A$4="Machamp",$I$10="Submission",$K$10=TRUE,D4>4,D4<11),'Atk Speed Boosts'!$C$86,0) +IF(AND($A$4="Machamp",$I$11="Submission+",$K$11=TRUE,D4>10),'Atk Speed Boosts'!$C$87,0) +IF(AND($A$4="Machamp",$I$12="Unite Buff",$K$12=TRUE,D4>8),'Atk Speed Boosts'!$C$88,0) +IF(AND($A$4="Meowscarada",$I$9="Hone Claws",$K$9=TRUE,D4<7),'Atk Speed Boosts'!$C$91,0) +IF(AND($A$4="Meowscarada",$I$10="Trail Blaze",$K$10=TRUE,D4>6),'Atk Speed Boosts'!$C$92,0) +IF(AND($A$4="Mewtwo Y",$I$9="Pressure",$K$9=TRUE),'Atk Speed Boosts'!$C$97*$L$9,0) +IF(AND($A$4="Mewtwo Y",$I$10="Mega Evolution",$K$10=TRUE,D4>4),'Atk Speed Boosts'!$C$98,0) +IF(AND($A$4="Ninetales",$I$9="Aurora Veil",$K$9=TRUE,D4>5),'Atk Speed Boosts'!$C$103,0) +IF(AND($A$4="Pawmot",$I$9="Fighter Mode",$K$9=TRUE,D4>8),'Atk Speed Boosts'!$C$105*$L$9,0) +IF(AND($A$4="Pawmot",$I$10="Unite Buff",$K$10=TRUE,D4>8),'Atk Speed Boosts'!$C$105,0) +IF(AND($A$4="Raichu",$I$9="Stored Power",$K$9=TRUE,D4>4),'Atk Speed Boosts'!$C$110,0) +IF(AND($A$4="Raichu",$I$10="Unite Buff",$K$10=TRUE,D4>8),'Atk Speed Boosts'!$C$111,0) +IF(AND($A$4="Tsareena",$I$9="Triple Axel",$K$9=TRUE,D4>4),('Atk Speed Boosts'!$C$126+'Atk Speed Boosts'!$D$126*(D4-1))*$L$9,0) +IF(AND($A$4="Zacian",$I$9="Metal Claw",$K$9=TRUE,D4>4),'Atk Speed Boosts'!$C$135,0) +IF(AND($A$4="Zeraora",$I$9="Agility",$K$9=TRUE,D4<5),'Atk Speed Boosts'!$C$137,0) +IF(AND($A$4="Zeraora",$I$10="Volt Switch",$K$10=TRUE,D4>4,D4<11),'Atk Speed Boosts'!$C$138,0) +IF(AND($A$4="Zeraora",$I$11="Volt Switch+",$K$11=TRUE,D4>10),'Atk Speed Boosts'!$C$139,0) +IF(AND($A$4="Zeraora",$I$12="Unite Buff",$K$12=TRUE,D4>8),'Atk Speed Boosts'!$C$140,0) -> 0 | E6: =IF($G$9=TRUE,'Atk Speed Boosts'!$C$9,0) +IF($G$10=TRUE,'Atk Speed Boosts'!$C$10,0)+$G$11 +IF(AND($A$4="Absol",$I$9="Feint",$K$9=TRUE,E4<5),'Atk Speed Boosts'!$C$11,0) +IF(AND($A$4="Absol",$I$10="Night Slash",$K$10=TRUE,E4>4),'Atk Speed Boosts'!$C$12,0) +IF(AND($A$4="Absol",$I$11="Sucker Punch+",$K$11=TRUE,E4>12),'Atk Speed Boosts'!$C$13,0) +IF(AND($A$4="Aegislash",$I$9="Sword Stance",$K$9=TRUE,E4>6),'Atk Speed Boosts'!$C$14,0) +IF(AND($A$4="Aegislash",$I$10="Shield Stance",$K$10=TRUE,E4>6),'Atk Speed Boosts'!$C$15,0) +IF(AND($A$4="Aegislash",$I$11="Stance Change",$K$11=TRUE,E4>6),'Atk Speed Boosts'!$C$16,0) +IF(AND($A$4="Azumarill",$I$9="Aqua Tail",$K$9=TRUE,E4>3),'Atk Speed Boosts'!$C$20,0) +IF(AND($A$4="Blaziken",$I$9="Punch Style",$K$9=TRUE,OR(E4<5,E4>7)),'Atk Speed Boosts'!$C$22,0) +IF(AND($A$4="Buzzwole",$I$9="Beast Boost Assist",$K$9=TRUE),'Atk Speed Boosts'!$C$24,0) +IF(AND($A$4="Buzzwole",$I$10="Beast Boost KO",$K$10=TRUE),'Atk Speed Boosts'!$C$25,0) +IF(AND($A$4="Buzzwole",$I$11="Lunge",$K$11=TRUE,E4>6),'Atk Speed Boosts'!$C$26,0) +IF(AND($A$4="Ceruledge",$I$9="Take Down",$K$9=TRUE,E4<7),'Atk Speed Boosts'!$C$27,0) +IF(AND($A$4="Ceruledge",$I$10="Flame Charge",$K$10=TRUE,E4>6),'Atk Speed Boosts'!$C$28,0) +IF(AND($A$4="Cinderace",$I$9="Blaze",$K$9=TRUE),'Atk Speed Boosts'!$C$33,0) +IF(AND($A$4="Cinderace",$I$10="Blaze Kick+",$K$10=TRUE,E4>10),'Atk Speed Boosts'!$C$34,0) +IF(AND($A$4="Cinderace",$I$11="Unite Buff",$K$11=TRUE,E4>8),'Atk Speed Boosts'!$C$35,0) +IF(AND($A$4="Decidueye",$I$9="Auto Attack",$K$9=TRUE),'Atk Speed Boosts'!$C$41*$L$9,0) +IF(AND($A$4="Decidueye",$I$10="Leafage",$K$10=TRUE,E4<7),'Atk Speed Boosts'!$C$42,0) +IF(AND($A$4="Decidueye",$I$11="Razor Leaf",$K$11=TRUE,E4>6),'Atk Speed Boosts'!$C$43+'Atk Speed Boosts'!$D$43*(E4-1),0) +IF(AND($A$4="Dragapult",$I$9="Quick Attack",$K$9=TRUE,E4<5),'Atk Speed Boosts'!$C$47,0) +IF(AND($A$4="Dragapult",$I$10="Dragon Dance",$K$10=TRUE,E4>4),'Atk Speed Boosts'!$C$48,0) +IF(AND($A$4="Dragapult",$I$11="Phantom Force",$K$11=TRUE,E4>4),'Atk Speed Boosts'!$C$49,0) +IF(AND($A$4="Dragonite",$I$9="Dragon Dance",$K$9=TRUE,E4>4),'Atk Speed Boosts'!$C$50,0) +IF(AND($A$4="Dragonite",$I$10="Outrage",$K$10=TRUE,E4>7),'Atk Speed Boosts'!$C$51,0) +IF(AND($A$4="Dragonite",$I$11="Unite Buff",$K$11=TRUE,E4>8),'Atk Speed Boosts'!$C$52,0) +IF(AND($A$4="Duraludon",$I$9="Flash Cannon",$K$9=TRUE,E4>4),'Atk Speed Boosts'!$C$53-20*$L$9,0) +IF(AND($A$4="Duraludon",$I$10="Unite Buff",$K$10=TRUE,E4>8),'Atk Speed Boosts'!$C$54,0) +IF(AND($A$4="Empoleon",$I$9="Aqua Jet",$K$9=TRUE,E4>4),'Atk Speed Boosts'!$C$56,0) +IF(AND($A$4="Falinks",$I$9="Bulk Up",$K$9=TRUE,E4<6),'Atk Speed Boosts'!$C$58,0) +IF(AND($A$4="Feraligatr",$I$9="Crunch",$K$9=TRUE,E4<4),'Atk Speed Boosts'!$C$59,0) +IF(AND($A$4="Feraligatr",$I$9="Unite Buff",$K$9=TRUE,E4<8),'Atk Speed Boosts'!$C$60,0) +IF(AND($A$4="Garchomp",$I$9="Boosted Attack",$K$9=TRUE),'Atk Speed Boosts'!$C$61+'Atk Speed Boosts'!$D$61*(E4-1),0) +IF(AND($A$4="Garchomp",$I$10="Sand Attack",$K$10=TRUE,E4<5),'Atk Speed Boosts'!$C$62,0) +IF(AND($A$4="Glaceon",$I$9="Eevee Bond",$K$9=TRUE),'Atk Speed Boosts'!$C$65,0) +IF(AND($A$4="Glaceon",$I$10="Ice Shard",$K$10=TRUE,E4>5,E4<12),'Atk Speed Boosts'!$C$66,0) +IF(AND($A$4="Glaceon",$I$11="Ice Shard+",$K$11=TRUE,E4>11),'Atk Speed Boosts'!$C$67,0) +IF(AND($A$4="Glaceon",$I$12="Unite Buff",$K$12=TRUE,E4>7),'Atk Speed Boosts'!$C$68,0) +IF(AND($A$4="Greninja",$I$9="Unite Buff",$K$9=TRUE,E4>8),'Atk Speed Boosts'!$C$71,0) +IF(AND($A$4="Gyarados",$I$9="Evolution",$K$9=TRUE),'Atk Speed Boosts'!$C$72,0) +IF(AND($A$4="Gyarados",$I$10="Dragon Breath",$K$10=TRUE),'Atk Speed Boosts'!$C$73+'Atk Speed Boosts'!$D$73*$L$10,0) +IF(AND($A$4="Gyarados [Mega]",$I$9="Evolution",$K$9=TRUE),'Atk Speed Boosts'!$C$74,0) +IF(AND($A$4="Gyarados [Mega]",$I$10="Dragon Breath",$K$10=TRUE),'Atk Speed Boosts'!$C$75+'Atk Speed Boosts'!$D$75*$L$10,0) +IF(AND($A$4="Inteleon",$I$9="Unite Buff",$K$9=TRUE,E4>8),'Atk Speed Boosts'!$C$78,0) +IF(AND($A$4="Machamp",$I$9="Bulk Up",$K$9=TRUE,E4<5),'Atk Speed Boosts'!$C$85,0) +IF(AND($A$4="Machamp",$I$10="Submission",$K$10=TRUE,E4>4,E4<11),'Atk Speed Boosts'!$C$86,0) +IF(AND($A$4="Machamp",$I$11="Submission+",$K$11=TRUE,E4>10),'Atk Speed Boosts'!$C$87,0) +IF(AND($A$4="Machamp",$I$12="Unite Buff",$K$12=TRUE,E4>8),'Atk Speed Boosts'!$C$88,0) +IF(AND($A$4="Meowscarada",$I$9="Hone Claws",$K$9=TRUE,E4<7),'Atk Speed Boosts'!$C$91,0) +IF(AND($A$4="Meowscarada",$I$10="Trail Blaze",$K$10=TRUE,E4>6),'Atk Speed Boosts'!$C$92,0) +IF(AND($A$4="Mewtwo Y",$I$9="Pressure",$K$9=TRUE),'Atk Speed Boosts'!$C$97*$L$9,0) +IF(AND($A$4="Mewtwo Y",$I$10="Mega Evolution",$K$10=TRUE,E4>4),'Atk Speed Boosts'!$C$98,0) +IF(AND($A$4="Ninetales",$I$9="Aurora Veil",$K$9=TRUE,E4>5),'Atk Speed Boosts'!$C$103,0) +IF(AND($A$4="Pawmot",$I$9="Fighter Mode",$K$9=TRUE,E4>8),'Atk Speed Boosts'!$C$105*$L$9,0) +IF(AND($A$4="Pawmot",$I$10="Unite Buff",$K$10=TRUE,E4>8),'Atk Speed Boosts'!$C$105,0) +IF(AND($A$4="Raichu",$I$9="Stored Power",$K$9=TRUE,E4>4),'Atk Speed Boosts'!$C$110,0) +IF(AND($A$4="Raichu",$I$10="Unite Buff",$K$10=TRUE,E4>8),'Atk Speed Boosts'!$C$111,0) +IF(AND($A$4="Tsareena",$I$9="Triple Axel",$K$9=TRUE,E4>4),('Atk Speed Boosts'!$C$126+'Atk Speed Boosts'!$D$126*(E4-1))*$L$9,0) +IF(AND($A$4="Zacian",$I$9="Metal Claw",$K$9=TRUE,E4>4),'Atk Speed Boosts'!$C$135,0) +IF(AND($A$4="Zeraora",$I$9="Agility",$K$9=TRUE,E4<5),'Atk Speed Boosts'!$C$137,0) +IF(AND($A$4="Zeraora",$I$10="Volt Switch",$K$10=TRUE,E4>4,E4<11),'Atk Speed Boosts'!$C$138,0) +IF(AND($A$4="Zeraora",$I$11="Volt Switch+",$K$11=TRUE,E4>10),'Atk Speed Boosts'!$C$139,0) +IF(AND($A$4="Zeraora",$I$12="Unite Buff",$K$12=TRUE,E4>8),'Atk Speed Boosts'!$C$140,0) -> 0 | F6: =IF($G$9=TRUE,'Atk Speed Boosts'!$C$9,0) +IF($G$10=TRUE,'Atk Speed Boosts'!$C$10,0)+$G$11 +IF(AND($A$4="Absol",$I$9="Feint",$K$9=TRUE,F4<5),'Atk Speed Boosts'!$C$11,0) +IF(AND($A$4="Absol",$I$10="Night Slash",$K$10=TRUE,F4>4),'Atk Speed Boosts'!$C$12,0) +IF(AND($A$4="Absol",$I$11="Sucker Punch+",$K$11=TRUE,F4>12),'Atk Speed Boosts'!$C$13,0) +IF(AND($A$4="Aegislash",$I$9="Sword Stance",$K$9=TRUE,F4>6),'Atk Speed Boosts'!$C$14,0) +IF(AND($A$4="Aegislash",$I$10="Shield Stance",$K$10=TRUE,F4>6),'Atk Speed Boosts'!$C$15,0) +IF(AND($A$4="Aegislash",$I$11="Stance Change",$K$11=TRUE,F4>6),'Atk Speed Boosts'!$C$16,0) +IF(AND($A$4="Azumarill",$I$9="Aqua Tail",$K$9=TRUE,F4>3),'Atk Speed Boosts'!$C$20,0) +IF(AND($A$4="Blaziken",$I$9="Punch Style",$K$9=TRUE,OR(F4<5,F4>7)),'Atk Speed Boosts'!$C$22,0) +IF(AND($A$4="Buzzwole",$I$9="Beast Boost Assist",$K$9=TRUE),'Atk Speed Boosts'!$C$24,0) +IF(AND($A$4="Buzzwole",$I$10="Beast Boost KO",$K$10=TRUE),'Atk Speed Boosts'!$C$25,0) +IF(AND($A$4="Buzzwole",$I$11="Lunge",$K$11=TRUE,F4>6),'Atk Speed Boosts'!$C$26,0) +IF(AND($A$4="Ceruledge",$I$9="Take Down",$K$9=TRUE,F4<7),'Atk Speed Boosts'!$C$27,0) +IF(AND($A$4="Ceruledge",$I$10="Flame Charge",$K$10=TRUE,F4>6),'Atk Speed Boosts'!$C$28,0) +IF(AND($A$4="Cinderace",$I$9="Blaze",$K$9=TRUE),'Atk Speed Boosts'!$C$33,0) +IF(AND($A$4="Cinderace",$I$10="Blaze Kick+",$K$10=TRUE,F4>10),'Atk Speed Boosts'!$C$34,0) +IF(AND($A$4="Cinderace",$I$11="Unite Buff",$K$11=TRUE,F4>8),'Atk Speed Boosts'!$C$35,0) +IF(AND($A$4="Decidueye",$I$9="Auto Attack",$K$9=TRUE),'Atk Speed Boosts'!$C$41*$L$9,0) +IF(AND($A$4="Decidueye",$I$10="Leafage",$K$10=TRUE,F4<7),'Atk Speed Boosts'!$C$42,0) +IF(AND($A$4="Decidueye",$I$11="Razor Leaf",$K$11=TRUE,F4>6),'Atk Speed Boosts'!$C$43+'Atk Speed Boosts'!$D$43*(F4-1),0) +IF(AND($A$4="Dragapult",$I$9="Quick Attack",$K$9=TRUE,F4<5),'Atk Speed Boosts'!$C$47,0) +IF(AND($A$4="Dragapult",$I$10="Dragon Dance",$K$10=TRUE,F4>4),'Atk Speed Boosts'!$C$48,0) +IF(AND($A$4="Dragapult",$I$11="Phantom Force",$K$11=TRUE,F4>4),'Atk Speed Boosts'!$C$49,0) +IF(AND($A$4="Dragonite",$I$9="Dragon Dance",$K$9=TRUE,F4>4),'Atk Speed Boosts'!$C$50,0) +IF(AND($A$4="Dragonite",$I$10="Outrage",$K$10=TRUE,F4>7),'Atk Speed Boosts'!$C$51,0) +IF(AND($A$4="Dragonite",$I$11="Unite Buff",$K$11=TRUE,F4>8),'Atk Speed Boosts'!$C$52,0) +IF(AND($A$4="Duraludon",$I$9="Flash Cannon",$K$9=TRUE,F4>4),'Atk Speed Boosts'!$C$53-20*$L$9,0) +IF(AND($A$4="Duraludon",$I$10="Unite Buff",$K$10=TRUE,F4>8),'Atk Speed Boosts'!$C$54,0) +IF(AND($A$4="Empoleon",$I$9="Aqua Jet",$K$9=TRUE,F4>4),'Atk Speed Boosts'!$C$56,0) +IF(AND($A$4="Falinks",$I$9="Bulk Up",$K$9=TRUE,F4<6),'Atk Speed Boosts'!$C$58,0) +IF(AND($A$4="Feraligatr",$I$9="Crunch",$K$9=TRUE,F4<4),'Atk Speed Boosts'!$C$59,0) +IF(AND($A$4="Feraligatr",$I$9="Unite Buff",$K$9=TRUE,F4<8),'Atk Speed Boosts'!$C$60,0) +IF(AND($A$4="Garchomp",$I$9="Boosted Attack",$K$9=TRUE),'Atk Speed Boosts'!$C$61+'Atk Speed Boosts'!$D$61*(F4-1),0) +IF(AND($A$4="Garchomp",$I$10="Sand Attack",$K$10=TRUE,F4<5),'Atk Speed Boosts'!$C$62,0) +IF(AND($A$4="Glaceon",$I$9="Eevee Bond",$K$9=TRUE),'Atk Speed Boosts'!$C$65,0) +IF(AND($A$4="Glaceon",$I$10="Ice Shard",$K$10=TRUE,F4>5,F4<12),'Atk Speed Boosts'!$C$66,0) +IF(AND($A$4="Glaceon",$I$11="Ice Shard+",$K$11=TRUE,F4>11),'Atk Speed Boosts'!$C$67,0) +IF(AND($A$4="Glaceon",$I$12="Unite Buff",$K$12=TRUE,F4>7),'Atk Speed Boosts'!$C$68,0) +IF(AND($A$4="Greninja",$I$9="Unite Buff",$K$9=TRUE,F4>8),'Atk Speed Boosts'!$C$71,0) +IF(AND($A$4="Gyarados",$I$9="Evolution",$K$9=TRUE),'Atk Speed Boosts'!$C$72,0) +IF(AND($A$4="Gyarados",$I$10="Dragon Breath",$K$10=TRUE),'Atk Speed Boosts'!$C$73+'Atk Speed Boosts'!$D$73*$L$10,0) +IF(AND($A$4="Gyarados [Mega]",$I$9="Evolution",$K$9=TRUE),'Atk Speed Boosts'!$C$74,0) +IF(AND($A$4="Gyarados [Mega]",$I$10="Dragon Breath",$K$10=TRUE),'Atk Speed Boosts'!$C$75+'Atk Speed Boosts'!$D$75*$L$10,0) +IF(AND($A$4="Inteleon",$I$9="Unite Buff",$K$9=TRUE,F4>8),'Atk Speed Boosts'!$C$78,0) +IF(AND($A$4="Machamp",$I$9="Bulk Up",$K$9=TRUE,F4<5),'Atk Speed Boosts'!$C$85,0) +IF(AND($A$4="Machamp",$I$10="Submission",$K$10=TRUE,F4>4,F4<11),'Atk Speed Boosts'!$C$86,0) +IF(AND($A$4="Machamp",$I$11="Submission+",$K$11=TRUE,F4>10),'Atk Speed Boosts'!$C$87,0) +IF(AND($A$4="Machamp",$I$12="Unite Buff",$K$12=TRUE,F4>8),'Atk Speed Boosts'!$C$88,0) +IF(AND($A$4="Meowscarada",$I$9="Hone Claws",$K$9=TRUE,F4<7),'Atk Speed Boosts'!$C$91,0) +IF(AND($A$4="Meowscarada",$I$10="Trail Blaze",$K$10=TRUE,F4>6),'Atk Speed Boosts'!$C$92,0) +IF(AND($A$4="Mewtwo Y",$I$9="Pressure",$K$9=TRUE),'Atk Speed Boosts'!$C$97*$L$9,0) +IF(AND($A$4="Mewtwo Y",$I$10="Mega Evolution",$K$10=TRUE,F4>4),'Atk Speed Boosts'!$C$98,0) +IF(AND($A$4="Ninetales",$I$9="Aurora Veil",$K$9=TRUE,F4>5),'Atk Speed Boosts'!$C$103,0) +IF(AND($A$4="Pawmot",$I$9="Fighter Mode",$K$9=TRUE,F4>8),'Atk Speed Boosts'!$C$105*$L$9,0) +IF(AND($A$4="Pawmot",$I$10="Unite Buff",$K$10=TRUE,F4>8),'Atk Speed Boosts'!$C$105,0) +IF(AND($A$4="Raichu",$I$9="Stored Power",$K$9=TRUE,F4>4),'Atk Speed Boosts'!$C$110,0) +IF(AND($A$4="Raichu",$I$10="Unite Buff",$K$10=TRUE,F4>8),'Atk Speed Boosts'!$C$111,0) +IF(AND($A$4="Tsareena",$I$9="Triple Axel",$K$9=TRUE,F4>4),('Atk Speed Boosts'!$C$126+'Atk Speed Boosts'!$D$126*(F4-1))*$L$9,0) +IF(AND($A$4="Zacian",$I$9="Metal Claw",$K$9=TRUE,F4>4),'Atk Speed Boosts'!$C$135,0) +IF(AND($A$4="Zeraora",$I$9="Agility",$K$9=TRUE,F4<5),'Atk Speed Boosts'!$C$137,0) +IF(AND($A$4="Zeraora",$I$10="Volt Switch",$K$10=TRUE,F4>4,F4<11),'Atk Speed Boosts'!$C$138,0) +IF(AND($A$4="Zeraora",$I$11="Volt Switch+",$K$11=TRUE,F4>10),'Atk Speed Boosts'!$C$139,0) +IF(AND($A$4="Zeraora",$I$12="Unite Buff",$K$12=TRUE,F4>8),'Atk Speed Boosts'!$C$140,0) -> 35 | G6: =IF($G$9=TRUE,'Atk Speed Boosts'!$C$9,0) +IF($G$10=TRUE,'Atk Speed Boosts'!$C$10,0)+$G$11 +IF(AND($A$4="Absol",$I$9="Feint",$K$9=TRUE,G4<5),'Atk Speed Boosts'!$C$11,0) +IF(AND($A$4="Absol",$I$10="Night Slash",$K$10=TRUE,G4>4),'Atk Speed Boosts'!$C$12,0) +IF(AND($A$4="Absol",$I$11="Sucker Punch+",$K$11=TRUE,G4>12),'Atk Speed Boosts'!$C$13,0) +IF(AND($A$4="Aegislash",$I$9="Sword Stance",$K$9=TRUE,G4>6),'Atk Speed Boosts'!$C$14,0) +IF(AND($A$4="Aegislash",$I$10="Shield Stance",$K$10=TRUE,G4>6),'Atk Speed Boosts'!$C$15,0) +IF(AND($A$4="Aegislash",$I$11="Stance Change",$K$11=TRUE,G4>6),'Atk Speed Boosts'!$C$16,0) +IF(AND($A$4="Azumarill",$I$9="Aqua Tail",$K$9=TRUE,G4>3),'Atk Speed Boosts'!$C$20,0) +IF(AND($A$4="Blaziken",$I$9="Punch Style",$K$9=TRUE,OR(G4<5,G4>7)),'Atk Speed Boosts'!$C$22,0) +IF(AND($A$4="Buzzwole",$I$9="Beast Boost Assist",$K$9=TRUE),'Atk Speed Boosts'!$C$24,0) +IF(AND($A$4="Buzzwole",$I$10="Beast Boost KO",$K$10=TRUE),'Atk Speed Boosts'!$C$25,0) +IF(AND($A$4="Buzzwole",$I$11="Lunge",$K$11=TRUE,G4>6),'Atk Speed Boosts'!$C$26,0) +IF(AND($A$4="Ceruledge",$I$9="Take Down",$K$9=TRUE,G4<7),'Atk Speed Boosts'!$C$27,0) +IF(AND($A$4="Ceruledge",$I$10="Flame Charge",$K$10=TRUE,G4>6),'Atk Speed Boosts'!$C$28,0) +IF(AND($A$4="Cinderace",$I$9="Blaze",$K$9=TRUE),'Atk Speed Boosts'!$C$33,0) +IF(AND($A$4="Cinderace",$I$10="Blaze Kick+",$K$10=TRUE,G4>10),'Atk Speed Boosts'!$C$34,0) +IF(AND($A$4="Cinderace",$I$11="Unite Buff",$K$11=TRUE,G4>8),'Atk Speed Boosts'!$C$35,0) +IF(AND($A$4="Decidueye",$I$9="Auto Attack",$K$9=TRUE),'Atk Speed Boosts'!$C$41*$L$9,0) +IF(AND($A$4="Decidueye",$I$10="Leafage",$K$10=TRUE,G4<7),'Atk Speed Boosts'!$C$42,0) +IF(AND($A$4="Decidueye",$I$11="Razor Leaf",$K$11=TRUE,G4>6),'Atk Speed Boosts'!$C$43+'Atk Speed Boosts'!$D$43*(G4-1),0) +IF(AND($A$4="Dragapult",$I$9="Quick Attack",$K$9=TRUE,G4<5),'Atk Speed Boosts'!$C$47,0) +IF(AND($A$4="Dragapult",$I$10="Dragon Dance",$K$10=TRUE,G4>4),'Atk Speed Boosts'!$C$48,0) +IF(AND($A$4="Dragapult",$I$11="Phantom Force",$K$11=TRUE,G4>4),'Atk Speed Boosts'!$C$49,0) +IF(AND($A$4="Dragonite",$I$9="Dragon Dance",$K$9=TRUE,G4>4),'Atk Speed Boosts'!$C$50,0) +IF(AND($A$4="Dragonite",$I$10="Outrage",$K$10=TRUE,G4>7),'Atk Speed Boosts'!$C$51,0) +IF(AND($A$4="Dragonite",$I$11="Unite Buff",$K$11=TRUE,G4>8),'Atk Speed Boosts'!$C$52,0) +IF(AND($A$4="Duraludon",$I$9="Flash Cannon",$K$9=TRUE,G4>4),'Atk Speed Boosts'!$C$53-20*$L$9,0) +IF(AND($A$4="Duraludon",$I$10="Unite Buff",$K$10=TRUE,G4>8),'Atk Speed Boosts'!$C$54,0) +IF(AND($A$4="Empoleon",$I$9="Aqua Jet",$K$9=TRUE,G4>4),'Atk Speed Boosts'!$C$56,0) +IF(AND($A$4="Falinks",$I$9="Bulk Up",$K$9=TRUE,G4<6),'Atk Speed Boosts'!$C$58,0) +IF(AND($A$4="Feraligatr",$I$9="Crunch",$K$9=TRUE,G4<4),'Atk Speed Boosts'!$C$59,0) +IF(AND($A$4="Feraligatr",$I$9="Unite Buff",$K$9=TRUE,G4<8),'Atk Speed Boosts'!$C$60,0) +IF(AND($A$4="Garchomp",$I$9="Boosted Attack",$K$9=TRUE),'Atk Speed Boosts'!$C$61+'Atk Speed Boosts'!$D$61*(G4-1),0) +IF(AND($A$4="Garchomp",$I$10="Sand Attack",$K$10=TRUE,G4<5),'Atk Speed Boosts'!$C$62,0) +IF(AND($A$4="Glaceon",$I$9="Eevee Bond",$K$9=TRUE),'Atk Speed Boosts'!$C$65,0) +IF(AND($A$4="Glaceon",$I$10="Ice Shard",$K$10=TRUE,G4>5,G4<12),'Atk Speed Boosts'!$C$66,0) +IF(AND($A$4="Glaceon",$I$11="Ice Shard+",$K$11=TRUE,G4>11),'Atk Speed Boosts'!$C$67,0) +IF(AND($A$4="Glaceon",$I$12="Unite Buff",$K$12=TRUE,G4>7),'Atk Speed Boosts'!$C$68,0) +IF(AND($A$4="Greninja",$I$9="Unite Buff",$K$9=TRUE,G4>8),'Atk Speed Boosts'!$C$71,0) +IF(AND($A$4="Gyarados",$I$9="Evolution",$K$9=TRUE),'Atk Speed Boosts'!$C$72,0) +IF(AND($A$4="Gyarados",$I$10="Dragon Breath",$K$10=TRUE),'Atk Speed Boosts'!$C$73+'Atk Speed Boosts'!$D$73*$L$10,0) +IF(AND($A$4="Gyarados [Mega]",$I$9="Evolution",$K$9=TRUE),'Atk Speed Boosts'!$C$74,0) +IF(AND($A$4="Gyarados [Mega]",$I$10="Dragon Breath",$K$10=TRUE),'Atk Speed Boosts'!$C$75+'Atk Speed Boosts'!$D$75*$L$10,0) +IF(AND($A$4="Inteleon",$I$9="Unite Buff",$K$9=TRUE,G4>8),'Atk Speed Boosts'!$C$78,0) +IF(AND($A$4="Machamp",$I$9="Bulk Up",$K$9=TRUE,G4<5),'Atk Speed Boosts'!$C$85,0) +IF(AND($A$4="Machamp",$I$10="Submission",$K$10=TRUE,G4>4,G4<11),'Atk Speed Boosts'!$C$86,0) +IF(AND($A$4="Machamp",$I$11="Submission+",$K$11=TRUE,G4>10),'Atk Speed Boosts'!$C$87,0) +IF(AND($A$4="Machamp",$I$12="Unite Buff",$K$12=TRUE,G4>8),'Atk Speed Boosts'!$C$88,0) +IF(AND($A$4="Meowscarada",$I$9="Hone Claws",$K$9=TRUE,G4<7),'Atk Speed Boosts'!$C$91,0) +IF(AND($A$4="Meowscarada",$I$10="Trail Blaze",$K$10=TRUE,G4>6),'Atk Speed Boosts'!$C$92,0) +IF(AND($A$4="Mewtwo Y",$I$9="Pressure",$K$9=TRUE),'Atk Speed Boosts'!$C$97*$L$9,0) +IF(AND($A$4="Mewtwo Y",$I$10="Mega Evolution",$K$10=TRUE,G4>4),'Atk Speed Boosts'!$C$98,0) +IF(AND($A$4="Ninetales",$I$9="Aurora Veil",$K$9=TRUE,G4>5),'Atk Speed Boosts'!$C$103,0) +IF(AND($A$4="Pawmot",$I$9="Fighter Mode",$K$9=TRUE,G4>8),'Atk Speed Boosts'!$C$105*$L$9,0) +IF(AND($A$4="Pawmot",$I$10="Unite Buff",$K$10=TRUE,G4>8),'Atk Speed Boosts'!$C$105,0) +IF(AND($A$4="Raichu",$I$9="Stored Power",$K$9=TRUE,G4>4),'Atk Speed Boosts'!$C$110,0) +IF(AND($A$4="Raichu",$I$10="Unite Buff",$K$10=TRUE,G4>8),'Atk Speed Boosts'!$C$111,0) +IF(AND($A$4="Tsareena",$I$9="Triple Axel",$K$9=TRUE,G4>4),('Atk Speed Boosts'!$C$126+'Atk Speed Boosts'!$D$126*(G4-1))*$L$9,0) +IF(AND($A$4="Zacian",$I$9="Metal Claw",$K$9=TRUE,G4>4),'Atk Speed Boosts'!$C$135,0) +IF(AND($A$4="Zeraora",$I$9="Agility",$K$9=TRUE,G4<5),'Atk Speed Boosts'!$C$137,0) +IF(AND($A$4="Zeraora",$I$10="Volt Switch",$K$10=TRUE,G4>4,G4<11),'Atk Speed Boosts'!$C$138,0) +IF(AND($A$4="Zeraora",$I$11="Volt Switch+",$K$11=TRUE,G4>10),'Atk Speed Boosts'!$C$139,0) +IF(AND($A$4="Zeraora",$I$12="Unite Buff",$K$12=TRUE,G4>8),'Atk Speed Boosts'!$C$140,0) -> 35 | H6: =IF($G$9=TRUE,'Atk Speed Boosts'!$C$9,0) +IF($G$10=TRUE,'Atk Speed Boosts'!$C$10,0)+$G$11 +IF(AND($A$4="Absol",$I$9="Feint",$K$9=TRUE,H4<5),'Atk Speed Boosts'!$C$11,0) +IF(AND($A$4="Absol",$I$10="Night Slash",$K$10=TRUE,H4>4),'Atk Speed Boosts'!$C$12,0) +IF(AND($A$4="Absol",$I$11="Sucker Punch+",$K$11=TRUE,H4>12),'Atk Speed Boosts'!$C$13,0) +IF(AND($A$4="Aegislash",$I$9="Sword Stance",$K$9=TRUE,H4>6),'Atk Speed Boosts'!$C$14,0) +IF(AND($A$4="Aegislash",$I$10="Shield Stance",$K$10=TRUE,H4>6),'Atk Speed Boosts'!$C$15,0) +IF(AND($A$4="Aegislash",$I$11="Stance Change",$K$11=TRUE,H4>6),'Atk Speed Boosts'!$C$16,0) +IF(AND($A$4="Azumarill",$I$9="Aqua Tail",$K$9=TRUE,H4>3),'Atk Speed Boosts'!$C$20,0) +IF(AND($A$4="Blaziken",$I$9="Punch Style",$K$9=TRUE,OR(H4<5,H4>7)),'Atk Speed Boosts'!$C$22,0) +IF(AND($A$4="Buzzwole",$I$9="Beast Boost Assist",$K$9=TRUE),'Atk Speed Boosts'!$C$24,0) +IF(AND($A$4="Buzzwole",$I$10="Beast Boost KO",$K$10=TRUE),'Atk Speed Boosts'!$C$25,0) +IF(AND($A$4="Buzzwole",$I$11="Lunge",$K$11=TRUE,H4>6),'Atk Speed Boosts'!$C$26,0) +IF(AND($A$4="Ceruledge",$I$9="Take Down",$K$9=TRUE,H4<7),'Atk Speed Boosts'!$C$27,0) +IF(AND($A$4="Ceruledge",$I$10="Flame Charge",$K$10=TRUE,H4>6),'Atk Speed Boosts'!$C$28,0) +IF(AND($A$4="Cinderace",$I$9="Blaze",$K$9=TRUE),'Atk Speed Boosts'!$C$33,0) +IF(AND($A$4="Cinderace",$I$10="Blaze Kick+",$K$10=TRUE,H4>10),'Atk Speed Boosts'!$C$34,0) +IF(AND($A$4="Cinderace",$I$11="Unite Buff",$K$11=TRUE,H4>8),'Atk Speed Boosts'!$C$35,0) +IF(AND($A$4="Decidueye",$I$9="Auto Attack",$K$9=TRUE),'Atk Speed Boosts'!$C$41*$L$9,0) +IF(AND($A$4="Decidueye",$I$10="Leafage",$K$10=TRUE,H4<7),'Atk Speed Boosts'!$C$42,0) +IF(AND($A$4="Decidueye",$I$11="Razor Leaf",$K$11=TRUE,H4>6),'Atk Speed Boosts'!$C$43+'Atk Speed Boosts'!$D$43*(H4-1),0) +IF(AND($A$4="Dragapult",$I$9="Quick Attack",$K$9=TRUE,H4<5),'Atk Speed Boosts'!$C$47,0) +IF(AND($A$4="Dragapult",$I$10="Dragon Dance",$K$10=TRUE,H4>4),'Atk Speed Boosts'!$C$48,0) +IF(AND($A$4="Dragapult",$I$11="Phantom Force",$K$11=TRUE,H4>4),'Atk Speed Boosts'!$C$49,0) +IF(AND($A$4="Dragonite",$I$9="Dragon Dance",$K$9=TRUE,H4>4),'Atk Speed Boosts'!$C$50,0) +IF(AND($A$4="Dragonite",$I$10="Outrage",$K$10=TRUE,H4>7),'Atk Speed Boosts'!$C$51,0) +IF(AND($A$4="Dragonite",$I$11="Unite Buff",$K$11=TRUE,H4>8),'Atk Speed Boosts'!$C$52,0) +IF(AND($A$4="Duraludon",$I$9="Flash Cannon",$K$9=TRUE,H4>4),'Atk Speed Boosts'!$C$53-20*$L$9,0) +IF(AND($A$4="Duraludon",$I$10="Unite Buff",$K$10=TRUE,H4>8),'Atk Speed Boosts'!$C$54,0) +IF(AND($A$4="Empoleon",$I$9="Aqua Jet",$K$9=TRUE,H4>4),'Atk Speed Boosts'!$C$56,0) +IF(AND($A$4="Falinks",$I$9="Bulk Up",$K$9=TRUE,H4<6),'Atk Speed Boosts'!$C$58,0) +IF(AND($A$4="Feraligatr",$I$9="Crunch",$K$9=TRUE,H4<4),'Atk Speed Boosts'!$C$59,0) +IF(AND($A$4="Feraligatr",$I$9="Unite Buff",$K$9=TRUE,H4<8),'Atk Speed Boosts'!$C$60,0) +IF(AND($A$4="Garchomp",$I$9="Boosted Attack",$K$9=TRUE),'Atk Speed Boosts'!$C$61+'Atk Speed Boosts'!$D$61*(H4-1),0) +IF(AND($A$4="Garchomp",$I$10="Sand Attack",$K$10=TRUE,H4<5),'Atk Speed Boosts'!$C$62,0) +IF(AND($A$4="Glaceon",$I$9="Eevee Bond",$K$9=TRUE),'Atk Speed Boosts'!$C$65,0) +IF(AND($A$4="Glaceon",$I$10="Ice Shard",$K$10=TRUE,H4>5,H4<12),'Atk Speed Boosts'!$C$66,0) +IF(AND($A$4="Glaceon",$I$11="Ice Shard+",$K$11=TRUE,H4>11),'Atk Speed Boosts'!$C$67,0) +IF(AND($A$4="Glaceon",$I$12="Unite Buff",$K$12=TRUE,H4>7),'Atk Speed Boosts'!$C$68,0) +IF(AND($A$4="Greninja",$I$9="Unite Buff",$K$9=TRUE,H4>8),'Atk Speed Boosts'!$C$71,0) +IF(AND($A$4="Gyarados",$I$9="Evolution",$K$9=TRUE),'Atk Speed Boosts'!$C$72,0) +IF(AND($A$4="Gyarados",$I$10="Dragon Breath",$K$10=TRUE),'Atk Speed Boosts'!$C$73+'Atk Speed Boosts'!$D$73*$L$10,0) +IF(AND($A$4="Gyarados [Mega]",$I$9="Evolution",$K$9=TRUE),'Atk Speed Boosts'!$C$74,0) +IF(AND($A$4="Gyarados [Mega]",$I$10="Dragon Breath",$K$10=TRUE),'Atk Speed Boosts'!$C$75+'Atk Speed Boosts'!$D$75*$L$10,0) +IF(AND($A$4="Inteleon",$I$9="Unite Buff",$K$9=TRUE,H4>8),'Atk Speed Boosts'!$C$78,0) +IF(AND($A$4="Machamp",$I$9="Bulk Up",$K$9=TRUE,H4<5),'Atk Speed Boosts'!$C$85,0) +IF(AND($A$4="Machamp",$I$10="Submission",$K$10=TRUE,H4>4,H4<11),'Atk Speed Boosts'!$C$86,0) +IF(AND($A$4="Machamp",$I$11="Submission+",$K$11=TRUE,H4>10),'Atk Speed Boosts'!$C$87,0) +IF(AND($A$4="Machamp",$I$12="Unite Buff",$K$12=TRUE,H4>8),'Atk Speed Boosts'!$C$88,0) +IF(AND($A$4="Meowscarada",$I$9="Hone Claws",$K$9=TRUE,H4<7),'Atk Speed Boosts'!$C$91,0) +IF(AND($A$4="Meowscarada",$I$10="Trail Blaze",$K$10=TRUE,H4>6),'Atk Speed Boosts'!$C$92,0) +IF(AND($A$4="Mewtwo Y",$I$9="Pressure",$K$9=TRUE),'Atk Speed Boosts'!$C$97*$L$9,0) +IF(AND($A$4="Mewtwo Y",$I$10="Mega Evolution",$K$10=TRUE,H4>4),'Atk Speed Boosts'!$C$98,0) +IF(AND($A$4="Ninetales",$I$9="Aurora Veil",$K$9=TRUE,H4>5),'Atk Speed Boosts'!$C$103,0) +IF(AND($A$4="Pawmot",$I$9="Fighter Mode",$K$9=TRUE,H4>8),'Atk Speed Boosts'!$C$105*$L$9,0) +IF(AND($A$4="Pawmot",$I$10="Unite Buff",$K$10=TRUE,H4>8),'Atk Speed Boosts'!$C$105,0) +IF(AND($A$4="Raichu",$I$9="Stored Power",$K$9=TRUE,H4>4),'Atk Speed Boosts'!$C$110,0) +IF(AND($A$4="Raichu",$I$10="Unite Buff",$K$10=TRUE,H4>8),'Atk Speed Boosts'!$C$111,0) +IF(AND($A$4="Tsareena",$I$9="Triple Axel",$K$9=TRUE,H4>4),('Atk Speed Boosts'!$C$126+'Atk Speed Boosts'!$D$126*(H4-1))*$L$9,0) +IF(AND($A$4="Zacian",$I$9="Metal Claw",$K$9=TRUE,H4>4),'Atk Speed Boosts'!$C$135,0) +IF(AND($A$4="Zeraora",$I$9="Agility",$K$9=TRUE,H4<5),'Atk Speed Boosts'!$C$137,0) +IF(AND($A$4="Zeraora",$I$10="Volt Switch",$K$10=TRUE,H4>4,H4<11),'Atk Speed Boosts'!$C$138,0) +IF(AND($A$4="Zeraora",$I$11="Volt Switch+",$K$11=TRUE,H4>10),'Atk Speed Boosts'!$C$139,0) +IF(AND($A$4="Zeraora",$I$12="Unite Buff",$K$12=TRUE,H4>8),'Atk Speed Boosts'!$C$140,0) -> 35 | I6: =IF($G$9=TRUE,'Atk Speed Boosts'!$C$9,0) +IF($G$10=TRUE,'Atk Speed Boosts'!$C$10,0)+$G$11 +IF(AND($A$4="Absol",$I$9="Feint",$K$9=TRUE,I4<5),'Atk Speed Boosts'!$C$11,0) +IF(AND($A$4="Absol",$I$10="Night Slash",$K$10=TRUE,I4>4),'Atk Speed Boosts'!$C$12,0) +IF(AND($A$4="Absol",$I$11="Sucker Punch+",$K$11=TRUE,I4>12),'Atk Speed Boosts'!$C$13,0) +IF(AND($A$4="Aegislash",$I$9="Sword Stance",$K$9=TRUE,I4>6),'Atk Speed Boosts'!$C$14,0) +IF(AND($A$4="Aegislash",$I$10="Shield Stance",$K$10=TRUE,I4>6),'Atk Speed Boosts'!$C$15,0) +IF(AND($A$4="Aegislash",$I$11="Stance Change",$K$11=TRUE,I4>6),'Atk Speed Boosts'!$C$16,0) +IF(AND($A$4="Azumarill",$I$9="Aqua Tail",$K$9=TRUE,I4>3),'Atk Speed Boosts'!$C$20,0) +IF(AND($A$4="Blaziken",$I$9="Punch Style",$K$9=TRUE,OR(I4<5,I4>7)),'Atk Speed Boosts'!$C$22,0) +IF(AND($A$4="Buzzwole",$I$9="Beast Boost Assist",$K$9=TRUE),'Atk Speed Boosts'!$C$24,0) +IF(AND($A$4="Buzzwole",$I$10="Beast Boost KO",$K$10=TRUE),'Atk Speed Boosts'!$C$25,0) +IF(AND($A$4="Buzzwole",$I$11="Lunge",$K$11=TRUE,I4>6),'Atk Speed Boosts'!$C$26,0) +IF(AND($A$4="Ceruledge",$I$9="Take Down",$K$9=TRUE,I4<7),'Atk Speed Boosts'!$C$27,0) +IF(AND($A$4="Ceruledge",$I$10="Flame Charge",$K$10=TRUE,I4>6),'Atk Speed Boosts'!$C$28,0) +IF(AND($A$4="Cinderace",$I$9="Blaze",$K$9=TRUE),'Atk Speed Boosts'!$C$33,0) +IF(AND($A$4="Cinderace",$I$10="Blaze Kick+",$K$10=TRUE,I4>10),'Atk Speed Boosts'!$C$34,0) +IF(AND($A$4="Cinderace",$I$11="Unite Buff",$K$11=TRUE,I4>8),'Atk Speed Boosts'!$C$35,0) +IF(AND($A$4="Decidueye",$I$9="Auto Attack",$K$9=TRUE),'Atk Speed Boosts'!$C$41*$L$9,0) +IF(AND($A$4="Decidueye",$I$10="Leafage",$K$10=TRUE,I4<7),'Atk Speed Boosts'!$C$42,0) +IF(AND($A$4="Decidueye",$I$11="Razor Leaf",$K$11=TRUE,I4>6),'Atk Speed Boosts'!$C$43+'Atk Speed Boosts'!$D$43*(I4-1),0) +IF(AND($A$4="Dragapult",$I$9="Quick Attack",$K$9=TRUE,I4<5),'Atk Speed Boosts'!$C$47,0) +IF(AND($A$4="Dragapult",$I$10="Dragon Dance",$K$10=TRUE,I4>4),'Atk Speed Boosts'!$C$48,0) +IF(AND($A$4="Dragapult",$I$11="Phantom Force",$K$11=TRUE,I4>4),'Atk Speed Boosts'!$C$49,0) +IF(AND($A$4="Dragonite",$I$9="Dragon Dance",$K$9=TRUE,I4>4),'Atk Speed Boosts'!$C$50,0) +IF(AND($A$4="Dragonite",$I$10="Outrage",$K$10=TRUE,I4>7),'Atk Speed Boosts'!$C$51,0) +IF(AND($A$4="Dragonite",$I$11="Unite Buff",$K$11=TRUE,I4>8),'Atk Speed Boosts'!$C$52,0) +IF(AND($A$4="Duraludon",$I$9="Flash Cannon",$K$9=TRUE,I4>4),'Atk Speed Boosts'!$C$53-20*$L$9,0) +IF(AND($A$4="Duraludon",$I$10="Unite Buff",$K$10=TRUE,I4>8),'Atk Speed Boosts'!$C$54,0) +IF(AND($A$4="Empoleon",$I$9="Aqua Jet",$K$9=TRUE,I4>4),'Atk Speed Boosts'!$C$56,0) +IF(AND($A$4="Falinks",$I$9="Bulk Up",$K$9=TRUE,I4<6),'Atk Speed Boosts'!$C$58,0) +IF(AND($A$4="Feraligatr",$I$9="Crunch",$K$9=TRUE,I4<4),'Atk Speed Boosts'!$C$59,0) +IF(AND($A$4="Feraligatr",$I$9="Unite Buff",$K$9=TRUE,I4<8),'Atk Speed Boosts'!$C$60,0) +IF(AND($A$4="Garchomp",$I$9="Boosted Attack",$K$9=TRUE),'Atk Speed Boosts'!$C$61+'Atk Speed Boosts'!$D$61*(I4-1),0) +IF(AND($A$4="Garchomp",$I$10="Sand Attack",$K$10=TRUE,I4<5),'Atk Speed Boosts'!$C$62,0) +IF(AND($A$4="Glaceon",$I$9="Eevee Bond",$K$9=TRUE),'Atk Speed Boosts'!$C$65,0) +IF(AND($A$4="Glaceon",$I$10="Ice Shard",$K$10=TRUE,I4>5,I4<12),'Atk Speed Boosts'!$C$66,0) +IF(AND($A$4="Glaceon",$I$11="Ice Shard+",$K$11=TRUE,I4>11),'Atk Speed Boosts'!$C$67,0) +IF(AND($A$4="Glaceon",$I$12="Unite Buff",$K$12=TRUE,I4>7),'Atk Speed Boosts'!$C$68,0) +IF(AND($A$4="Greninja",$I$9="Unite Buff",$K$9=TRUE,I4>8),'Atk Speed Boosts'!$C$71,0) +IF(AND($A$4="Gyarados",$I$9="Evolution",$K$9=TRUE),'Atk Speed Boosts'!$C$72,0) +IF(AND($A$4="Gyarados",$I$10="Dragon Breath",$K$10=TRUE),'Atk Speed Boosts'!$C$73+'Atk Speed Boosts'!$D$73*$L$10,0) +IF(AND($A$4="Gyarados [Mega]",$I$9="Evolution",$K$9=TRUE),'Atk Speed Boosts'!$C$74,0) +IF(AND($A$4="Gyarados [Mega]",$I$10="Dragon Breath",$K$10=TRUE),'Atk Speed Boosts'!$C$75+'Atk Speed Boosts'!$D$75*$L$10,0) +IF(AND($A$4="Inteleon",$I$9="Unite Buff",$K$9=TRUE,I4>8),'Atk Speed Boosts'!$C$78,0) +IF(AND($A$4="Machamp",$I$9="Bulk Up",$K$9=TRUE,I4<5),'Atk Speed Boosts'!$C$85,0) +IF(AND($A$4="Machamp",$I$10="Submission",$K$10=TRUE,I4>4,I4<11),'Atk Speed Boosts'!$C$86,0) +IF(AND($A$4="Machamp",$I$11="Submission+",$K$11=TRUE,I4>10),'Atk Speed Boosts'!$C$87,0) +IF(AND($A$4="Machamp",$I$12="Unite Buff",$K$12=TRUE,I4>8),'Atk Speed Boosts'!$C$88,0) +IF(AND($A$4="Meowscarada",$I$9="Hone Claws",$K$9=TRUE,I4<7),'Atk Speed Boosts'!$C$91,0) +IF(AND($A$4="Meowscarada",$I$10="Trail Blaze",$K$10=TRUE,I4>6),'Atk Speed Boosts'!$C$92,0) +IF(AND($A$4="Mewtwo Y",$I$9="Pressure",$K$9=TRUE),'Atk Speed Boosts'!$C$97*$L$9,0) +IF(AND($A$4="Mewtwo Y",$I$10="Mega Evolution",$K$10=TRUE,I4>4),'Atk Speed Boosts'!$C$98,0) +IF(AND($A$4="Ninetales",$I$9="Aurora Veil",$K$9=TRUE,I4>5),'Atk Speed Boosts'!$C$103,0) +IF(AND($A$4="Pawmot",$I$9="Fighter Mode",$K$9=TRUE,I4>8),'Atk Speed Boosts'!$C$105*$L$9,0) +IF(AND($A$4="Pawmot",$I$10="Unite Buff",$K$10=TRUE,I4>8),'Atk Speed Boosts'!$C$105,0) +IF(AND($A$4="Raichu",$I$9="Stored Power",$K$9=TRUE,I4>4),'Atk Speed Boosts'!$C$110,0) +IF(AND($A$4="Raichu",$I$10="Unite Buff",$K$10=TRUE,I4>8),'Atk Speed Boosts'!$C$111,0) +IF(AND($A$4="Tsareena",$I$9="Triple Axel",$K$9=TRUE,I4>4),('Atk Speed Boosts'!$C$126+'Atk Speed Boosts'!$D$126*(I4-1))*$L$9,0) +IF(AND($A$4="Zacian",$I$9="Metal Claw",$K$9=TRUE,I4>4),'Atk Speed Boosts'!$C$135,0) +IF(AND($A$4="Zeraora",$I$9="Agility",$K$9=TRUE,I4<5),'Atk Speed Boosts'!$C$137,0) +IF(AND($A$4="Zeraora",$I$10="Volt Switch",$K$10=TRUE,I4>4,I4<11),'Atk Speed Boosts'!$C$138,0) +IF(AND($A$4="Zeraora",$I$11="Volt Switch+",$K$11=TRUE,I4>10),'Atk Speed Boosts'!$C$139,0) +IF(AND($A$4="Zeraora",$I$12="Unite Buff",$K$12=TRUE,I4>8),'Atk Speed Boosts'!$C$140,0) -> 35 | ... P6: =IF($G$9=TRUE,'Atk Speed Boosts'!$C$9,0) +IF($G$10=TRUE,'Atk Speed Boosts'!$C$10,0)+$G$11 +IF(AND($A$4="Absol",$I$9="Feint",$K$9=TRUE,P4<5),'Atk Speed Boosts'!$C$11,0) +IF(AND($A$4="Absol",$I$10="Night Slash",$K$10=TRUE,P4>4),'Atk Speed Boosts'!$C$12,0) +IF(AND($A$4="Absol",$I$11="Sucker Punch+",$K$11=TRUE,P4>12),'Atk Speed Boosts'!$C$13,0) +IF(AND($A$4="Aegislash",$I$9="Sword Stance",$K$9=TRUE,P4>6),'Atk Speed Boosts'!$C$14,0) +IF(AND($A$4="Aegislash",$I$10="Shield Stance",$K$10=TRUE,P4>6),'Atk Speed Boosts'!$C$15,0) +IF(AND($A$4="Aegislash",$I$11="Stance Change",$K$11=TRUE,P4>6),'Atk Speed Boosts'!$C$16,0) +IF(AND($A$4="Azumarill",$I$9="Aqua Tail",$K$9=TRUE,P4>3),'Atk Speed Boosts'!$C$20,0) +IF(AND($A$4="Blaziken",$I$9="Punch Style",$K$9=TRUE,OR(P4<5,P4>7)),'Atk Speed Boosts'!$C$22,0) +IF(AND($A$4="Buzzwole",$I$9="Beast Boost Assist",$K$9=TRUE),'Atk Speed Boosts'!$C$24,0) +IF(AND($A$4="Buzzwole",$I$10="Beast Boost KO",$K$10=TRUE),'Atk Speed Boosts'!$C$25,0) +IF(AND($A$4="Buzzwole",$I$11="Lunge",$K$11=TRUE,P4>6),'Atk Speed Boosts'!$C$26,0) +IF(AND($A$4="Ceruledge",$I$9="Take Down",$K$9=TRUE,P4<7),'Atk Speed Boosts'!$C$27,0) +IF(AND($A$4="Ceruledge",$I$10="Flame Charge",$K$10=TRUE,P4>6),'Atk Speed Boosts'!$C$28,0) +IF(AND($A$4="Cinderace",$I$9="Blaze",$K$9=TRUE),'Atk Speed Boosts'!$C$33,0) +IF(AND($A$4="Cinderace",$I$10="Blaze Kick+",$K$10=TRUE,P4>10),'Atk Speed Boosts'!$C$34,0) +IF(AND($A$4="Cinderace",$I$11="Unite Buff",$K$11=TRUE,P4>8),'Atk Speed Boosts'!$C$35,0) +IF(AND($A$4="Decidueye",$I$9="Auto Attack",$K$9=TRUE),'Atk Speed Boosts'!$C$41*$L$9,0) +IF(AND($A$4="Decidueye",$I$10="Leafage",$K$10=TRUE,P4<7),'Atk Speed Boosts'!$C$42,0) +IF(AND($A$4="Decidueye",$I$11="Razor Leaf",$K$11=TRUE,P4>6),'Atk Speed Boosts'!$C$43+'Atk Speed Boosts'!$D$43*(P4-1),0) +IF(AND($A$4="Dragapult",$I$9="Quick Attack",$K$9=TRUE,P4<5),'Atk Speed Boosts'!$C$47,0) +IF(AND($A$4="Dragapult",$I$10="Dragon Dance",$K$10=TRUE,P4>4),'Atk Speed Boosts'!$C$48,0) +IF(AND($A$4="Dragapult",$I$11="Phantom Force",$K$11=TRUE,P4>4),'Atk Speed Boosts'!$C$49,0) +IF(AND($A$4="Dragonite",$I$9="Dragon Dance",$K$9=TRUE,P4>4),'Atk Speed Boosts'!$C$50,0) +IF(AND($A$4="Dragonite",$I$10="Outrage",$K$10=TRUE,P4>7),'Atk Speed Boosts'!$C$51,0) +IF(AND($A$4="Dragonite",$I$11="Unite Buff",$K$11=TRUE,P4>8),'Atk Speed Boosts'!$C$52,0) +IF(AND($A$4="Duraludon",$I$9="Flash Cannon",$K$9=TRUE,P4>4),'Atk Speed Boosts'!$C$53-20*$L$9,0) +IF(AND($A$4="Duraludon",$I$10="Unite Buff",$K$10=TRUE,P4>8),'Atk Speed Boosts'!$C$54,0) +IF(AND($A$4="Empoleon",$I$9="Aqua Jet",$K$9=TRUE,P4>4),'Atk Speed Boosts'!$C$56,0) +IF(AND($A$4="Falinks",$I$9="Bulk Up",$K$9=TRUE,P4<6),'Atk Speed Boosts'!$C$58,0) +IF(AND($A$4="Feraligatr",$I$9="Crunch",$K$9=TRUE,P4<4),'Atk Speed Boosts'!$C$59,0) +IF(AND($A$4="Feraligatr",$I$9="Unite Buff",$K$9=TRUE,P4<8),'Atk Speed Boosts'!$C$60,0) +IF(AND($A$4="Garchomp",$I$9="Boosted Attack",$K$9=TRUE),'Atk Speed Boosts'!$C$61+'Atk Speed Boosts'!$D$61*(P4-1),0) +IF(AND($A$4="Garchomp",$I$10="Sand Attack",$K$10=TRUE,P4<5),'Atk Speed Boosts'!$C$62,0) +IF(AND($A$4="Glaceon",$I$9="Eevee Bond",$K$9=TRUE),'Atk Speed Boosts'!$C$65,0) +IF(AND($A$4="Glaceon",$I$10="Ice Shard",$K$10=TRUE,P4>5,P4<12),'Atk Speed Boosts'!$C$66,0) +IF(AND($A$4="Glaceon",$I$11="Ice Shard+",$K$11=TRUE,P4>11),'Atk Speed Boosts'!$C$67,0) +IF(AND($A$4="Glaceon",$I$12="Unite Buff",$K$12=TRUE,P4>7),'Atk Speed Boosts'!$C$68,0) +IF(AND($A$4="Greninja",$I$9="Unite Buff",$K$9=TRUE,P4>8),'Atk Speed Boosts'!$C$71,0) +IF(AND($A$4="Gyarados",$I$9="Evolution",$K$9=TRUE),'Atk Speed Boosts'!$C$72,0) +IF(AND($A$4="Gyarados",$I$10="Dragon Breath",$K$10=TRUE),'Atk Speed Boosts'!$C$73+'Atk Speed Boosts'!$D$73*$L$10,0) +IF(AND($A$4="Gyarados [Mega]",$I$9="Evolution",$K$9=TRUE),'Atk Speed Boosts'!$C$74,0) +IF(AND($A$4="Gyarados [Mega]",$I$10="Dragon Breath",$K$10=TRUE),'Atk Speed Boosts'!$C$75+'Atk Speed Boosts'!$D$75*$L$10,0) +IF(AND($A$4="Inteleon",$I$9="Unite Buff",$K$9=TRUE,P4>8),'Atk Speed Boosts'!$C$78,0) +IF(AND($A$4="Machamp",$I$9="Bulk Up",$K$9=TRUE,P4<5),'Atk Speed Boosts'!$C$85,0) +IF(AND($A$4="Machamp",$I$10="Submission",$K$10=TRUE,P4>4,P4<11),'Atk Speed Boosts'!$C$86,0) +IF(AND($A$4="Machamp",$I$11="Submission+",$K$11=TRUE,P4>10),'Atk Speed Boosts'!$C$87,0) +IF(AND($A$4="Machamp",$I$12="Unite Buff",$K$12=TRUE,P4>8),'Atk Speed Boosts'!$C$88,0) +IF(AND($A$4="Meowscarada",$I$9="Hone Claws",$K$9=TRUE,P4<7),'Atk Speed Boosts'!$C$91,0) +IF(AND($A$4="Meowscarada",$I$10="Trail Blaze",$K$10=TRUE,P4>6),'Atk Speed Boosts'!$C$92,0) +IF(AND($A$4="Mewtwo Y",$I$9="Pressure",$K$9=TRUE),'Atk Speed Boosts'!$C$97*$L$9,0) +IF(AND($A$4="Mewtwo Y",$I$10="Mega Evolution",$K$10=TRUE,P4>4),'Atk Speed Boosts'!$C$98,0) +IF(AND($A$4="Ninetales",$I$9="Aurora Veil",$K$9=TRUE,P4>5),'Atk Speed Boosts'!$C$103,0) +IF(AND($A$4="Pawmot",$I$9="Fighter Mode",$K$9=TRUE,P4>8),'Atk Speed Boosts'!$C$105*$L$9,0) +IF(AND($A$4="Pawmot",$I$10="Unite Buff",$K$10=TRUE,P4>8),'Atk Speed Boosts'!$C$105,0) +IF(AND($A$4="Raichu",$I$9="Stored Power",$K$9=TRUE,P4>4),'Atk Speed Boosts'!$C$110,0) +IF(AND($A$4="Raichu",$I$10="Unite Buff",$K$10=TRUE,P4>8),'Atk Speed Boosts'!$C$111,0) +IF(AND($A$4="Tsareena",$I$9="Triple Axel",$K$9=TRUE,P4>4),('Atk Speed Boosts'!$C$126+'Atk Speed Boosts'!$D$126*(P4-1))*$L$9,0) +IF(AND($A$4="Zacian",$I$9="Metal Claw",$K$9=TRUE,P4>4),'Atk Speed Boosts'!$C$135,0) +IF(AND($A$4="Zeraora",$I$9="Agility",$K$9=TRUE,P4<5),'Atk Speed Boosts'!$C$137,0) +IF(AND($A$4="Zeraora",$I$10="Volt Switch",$K$10=TRUE,P4>4,P4<11),'Atk Speed Boosts'!$C$138,0) +IF(AND($A$4="Zeraora",$I$11="Volt Switch+",$K$11=TRUE,P4>10),'Atk Speed Boosts'!$C$139,0) +IF(AND($A$4="Zeraora",$I$12="Unite Buff",$K$12=TRUE,P4>8),'Atk Speed Boosts'!$C$140,0) -> 35
A7: Multiplicative Attack Speed | B7: =$G$12 -> 0 | C7: =$G$12 -> 0 | D7: =$G$12 -> 0 | E7: =$G$12 -> 0 | F7: =$G$12 -> 0 | G7: =$G$12 -> 0 | H7: =$G$12 -> 0 | I7: =$G$12 -> 0 | ... P7: =$G$12 -> 0
A9: Items | B9: Build A | C9: Build B | D9: Universal Attack Speed Boost Effects | E9: Blissey Helping Hand | G9: FALSE | H9: Attack Speed Boost Effects | I9: =IFERROR(__xludf.DUMMYFUNCTION("FILTER('Atk Speed Boosts'!B:B,'Atk Speed Boosts'!A:A=A4)"),"Pressure") -> Pressure | K9: FALSE | L9: 0 | N9: =IF($A$4="Charizard","Charizard's auto attack speed is locked to 76 Frames","") & IF($A$4="Charizard [Mega X]","Charizard's auto attack speed is locked to 76 Frames","") & IF($A$4="Charizard [Mega Y]","Charizard's auto attack speed is locked to 76 Frames","")
A10: X-Atk | B10: FALSE | C10: FALSE | E10: Mew Coaching | G10: FALSE | I10: =IFERROR(__xludf.DUMMYFUNCTION("""COMPUTED_VALUE"""),"Mega Evolution") -> Mega Evolution | K10: TRUE | L10: 0
A11: Muscle Band | B11: TRUE | C11: TRUE | E11: Other (Additive) | G11: 0 | K11: FALSE | L11: 0
A12: Rapid Fire Scarf | B12: FALSE | C12: TRUE | E12: Other (Multiplier) | G12: 0 | K12: FALSE | L12: 0
A13: Rapid Fire Scarf Proc | B13: FALSE | C13: FALSE | K13: FALSE | L13: 0
A14: Choice Scarf | B14: FALSE | C14: FALSE | K14: FALSE | L14: 0
A15: Red Emblems | B15: - | C15: - | K15: FALSE | L15: 0
A17: Total Attack Speed | B17: 1 | C17: 2 | D17: 3 | E17: 4 | F17: 5 | G17: 6 | H17: 7 | I17: 8 | J17: 9 | K17: 10 | L17: 11 | M17: 12 | N17: 13 | O17: 14 | P17: 15
A18: No Items | B18: {=(B5:P5+B6:P6)*(1+B7:P7)} -> 10 | C18: 11.42 | D18: 12.99 | E18: 14.71 | F18: 51.6 | G18: 53.68 | H18: 55.97 | I18: 58.49 | J18: 61.27 | K18: 64.34 | L18: 67.72 | M18: 71.44 | N18: 75.53 | O18: 80.03 | P18: 84.99
A19: Build A | B19: {=(B5:P5+B6:P6+IF($B$10,'Atk Speed Boosts'!$C$1,0)+IF($B$11,'Atk Speed Boosts'!$C$2,0)+IF($B$12,'Atk Speed Boosts'!$C$3,0)+IF($B$13,'Atk Speed Boosts'!$C$4,0)+IF($B$14,'Atk Speed Boosts'!$C$5,0)+IF($B$15="Red 3",'Atk Speed Boosts'!$C$6,0)+IF($B$15="Red 5",'Atk Speed Boosts'!$C$7,0)+IF($B$15="Red 7",'Atk Speed Boosts'!$C$8,0)) * (1+B7:P7)} -> 18.75 | C19: 20.17 | D19: 21.74 | E19: 23.46 | F19: 60.35 | G19: 62.43 | H19: 64.72 | I19: 67.24 | J19: 70.02 | K19: 73.09 | L19: 76.47 | M19: 80.19 | N19: 84.28 | O19: 88.78 | P19: 93.74
A20: Build B | B20: {=(B5:P5+B6:P6+IF($C$10,'Atk Speed Boosts'!$C$1,0)+IF($C$11,'Atk Speed Boosts'!$C$2,0)+IF($C$12,'Atk Speed Boosts'!$C$3,0)+IF($C$13,'Atk Speed Boosts'!$C$4,0)+IF($C$14,'Atk Speed Boosts'!$C$5,0)+IF($C$15="Red 3",'Atk Speed Boosts'!$C$6,0)+IF($C$15="Red 5",'Atk Speed Boosts'!$C$7,0)+IF($C$15="Red 7",'Atk Speed Boosts'!$C$8,0)) * (1+B7:P7)} -> 29.25 | C20: 30.67 | D20: 32.24 | E20: 33.96 | F20: 70.85 | G20: 72.93 | H20: 75.22 | I20: 77.74 | J20: 80.52 | K20: 83.59 | L20: 86.97 | M20: 90.69 | N20: 94.78 | O20: 99.28 | P20: 104.24
A22: Attack Speed Frames | B22: 1 | C22: 2 | D22: 3 | E22: 4 | F22: 5 | G22: 6 | H22: 7 | I22: 8 | J22: 9 | K22: 10 | L22: 11 | M22: 12 | N22: 13 | O22: 14 | P22: 15
A23: No Items | B23: =IFS(B18 > 272.5, 16, B18 > 202.4, 20, B18 > 151.81, 24, B18 > 115.99, 28, B18 > 89.04, 32, B18 > 68.05, 36, B18 > 51.29, 40, B18 > 37.56, 44, B18 > 26.11, 48, B18 > 16.42, 52, B18 > 8.1, 56, B18 >= 0, 60, B18 < 0 , 60) -> 56 | C23: =IFS(C18 > 272.5, 16, C18 > 202.4, 20, C18 > 151.81, 24, C18 > 115.99, 28, C18 > 89.04, 32, C18 > 68.05, 36, C18 > 51.29, 40, C18 > 37.56, 44, C18 > 26.11, 48, C18 > 16.42, 52, C18 > 8.1, 56, C18 >= 0, 60, C18 < 0 , 60) -> 56 | D23: =IFS(D18 > 272.5, 16, D18 > 202.4, 20, D18 > 151.81, 24, D18 > 115.99, 28, D18 > 89.04, 32, D18 > 68.05, 36, D18 > 51.29, 40, D18 > 37.56, 44, D18 > 26.11, 48, D18 > 16.42, 52, D18 > 8.1, 56, D18 >= 0, 60, D18 < 0 , 60) -> 56 | E23: =IFS(E18 > 272.5, 16, E18 > 202.4, 20, E18 > 151.81, 24, E18 > 115.99, 28, E18 > 89.04, 32, E18 > 68.05, 36, E18 > 51.29, 40, E18 > 37.56, 44, E18 > 26.11, 48, E18 > 16.42, 52, E18 > 8.1, 56, E18 >= 0, 60, E18 < 0 , 60) -> 56 | F23: =IFS(F18 > 272.5, 16, F18 > 202.4, 20, F18 > 151.81, 24, F18 > 115.99, 28, F18 > 89.04, 32, F18 > 68.05, 36, F18 > 51.29, 40, F18 > 37.56, 44, F18 > 26.11, 48, F18 > 16.42, 52, F18 > 8.1, 56, F18 >= 0, 60, F18 < 0 , 60) -> 40 | G23: =IFS(G18 > 272.5, 16, G18 > 202.4, 20, G18 > 151.81, 24, G18 > 115.99, 28, G18 > 89.04, 32, G18 > 68.05, 36, G18 > 51.29, 40, G18 > 37.56, 44, G18 > 26.11, 48, G18 > 16.42, 52, G18 > 8.1, 56, G18 >= 0, 60, G18 < 0 , 60) -> 40 | H23: =IFS(H18 > 272.5, 16, H18 > 202.4, 20, H18 > 151.81, 24, H18 > 115.99, 28, H18 > 89.04, 32, H18 > 68.05, 36, H18 > 51.29, 40, H18 > 37.56, 44, H18 > 26.11, 48, H18 > 16.42, 52, H18 > 8.1, 56, H18 >= 0, 60, H18 < 0 , 60) -> 40 | I23: =IFS(I18 > 272.5, 16, I18 > 202.4, 20, I18 > 151.81, 24, I18 > 115.99, 28, I18 > 89.04, 32, I18 > 68.05, 36, I18 > 51.29, 40, I18 > 37.56, 44, I18 > 26.11, 48, I18 > 16.42, 52, I18 > 8.1, 56, I18 >= 0, 60, I18 < 0 , 60) -> 40 | ... P23: =IFS(P18 > 272.5, 16, P18 > 202.4, 20, P18 > 151.81, 24, P18 > 115.99, 28, P18 > 89.04, 32, P18 > 68.05, 36, P18 > 51.29, 40, P18 > 37.56, 44, P18 > 26.11, 48, P18 > 16.42, 52, P18 > 8.1, 56, P18 >= 0, 60, P18 < 0 , 60) -> 36
